{"cells":[{"cell_type":"markdown","metadata":{"id":"Wu2v6tnMYf3v"},"source":["## Google Drive and GitHub initialization"]},{"cell_type":"code","execution_count":null,"metadata":{"id":"1K_InM4uapiq"},"outputs":[],"source":["# Settings\n","DRIVEmount = True\n","GHpush = True\n","\n","from google.colab import drive\n","import os\n","from pathlib import Path\n","from datetime import datetime"]},{"cell_type":"code","execution_count":1,"metadata":{"colab":{"background_save":true,"base_uri":"https://localhost:8080/"},"executionInfo":{"elapsed":5636,"status":"ok","timestamp":1740844180113,"user":{"displayName":"Matteo Spadaccia","userId":"07886475442363014775"},"user_tz":0},"id":"Ofleomj8XZL2"},"outputs":[{"name":"stderr","output_type":"stream","text":["ERROR:root:Internal Python error in the inspect module.\n","Below is the traceback from this internal error.\n","\n","ERROR:root:Internal Python error in the inspect module.\n","Below is the traceback from this internal error.\n","\n","ERROR:root:Internal Python error in the inspect module.\n","Below is the traceback from this internal error.\n","\n"]},{"name":"stdout","output_type":"stream","text":["Mounted at /content/drive\n","Traceback (most recent call last):\n","  File \"/usr/local/lib/python3.11/dist-packages/IPython/core/interactiveshell.py\", line 3553, in run_code\n","    exec(code_obj, self.user_global_ns, self.user_ns)\n","  File \"\u003cipython-input-3-25625e750ebd\u003e\", line 12, in \u003ccell line: 0\u003e\n","    get_ipython().run_line_magic('cd', '\"{path}\"')\n","  File \"/usr/local/lib/python3.11/dist-packages/IPython/core/interactiveshell.py\", line 2418, in run_line_magic\n","    result = fn(*args, **kwargs)\n","             ^^^^^^^^^^^^^^^^^^^\n","  File \"\u003cdecorator-gen-85\u003e\", line 2, in cd\n","  File \"/usr/local/lib/python3.11/dist-packages/IPython/core/magic.py\", line 187, in \u003clambda\u003e\n","    call = lambda f, *a, **k: f(*a, **k)\n","                              ^^^^^^^^^^\n","  File \"/usr/local/lib/python3.11/dist-packages/IPython/core/magics/osm.py\", line 342, in cd\n","    oldcwd = os.getcwd()\n","             ^^^^^^^^^^^\n","OSError: [Errno 107] Transport endpoint is not connected\n","\n","During handling of the above exception, another exception occurred:\n","\n","Traceback (most recent call last):\n","  File \"/usr/local/lib/python3.11/dist-packages/IPython/core/interactiveshell.py\", line 2099, in showtraceback\n","    stb = value._render_traceback_()\n","          ^^^^^^^^^^^^^^^^^^^^^^^^\n","AttributeError: 'OSError' object has no attribute '_render_traceback_'\n","\n","During handling of the above exception, another exception occurred:\n","\n","Traceback (most recent call last):\n","  File \"/usr/local/lib/python3.11/dist-packages/IPython/core/ultratb.py\", line 1101, in get_records\n","    return _fixed_getinnerframes(etb, number_of_lines_of_context, tb_offset)\n","           ^^^^^^^^^^^^^^^^^^^^^^^^^^^^^^^^^^^^^^^^^^^^^^^^^^^^^^^^^^^^^^^^^\n","  File \"/usr/local/lib/python3.11/dist-packages/IPython/core/ultratb.py\", line 248, in wrapped\n","    return f(*args, **kwargs)\n","           ^^^^^^^^^^^^^^^^^^\n","  File \"/usr/local/lib/python3.11/dist-packages/IPython/core/ultratb.py\", line 281, in _fixed_getinnerframes\n","    records = fix_frame_records_filenames(inspect.getinnerframes(etb, context))\n","                                          ^^^^^^^^^^^^^^^^^^^^^^^^^^^^^^^^^^^^\n","  File \"/usr/lib/python3.11/inspect.py\", line 1739, in getinnerframes\n","    traceback_info = getframeinfo(tb, context)\n","                     ^^^^^^^^^^^^^^^^^^^^^^^^^\n","  File \"/usr/lib/python3.11/inspect.py\", line 1684, in getframeinfo\n","    filename = getsourcefile(frame) or getfile(frame)\n","               ^^^^^^^^^^^^^^^^^^^^\n","  File \"/usr/lib/python3.11/inspect.py\", line 948, in getsourcefile\n","    module = getmodule(object, filename)\n","             ^^^^^^^^^^^^^^^^^^^^^^^^^^^\n","  File \"/usr/lib/python3.11/inspect.py\", line 980, in getmodule\n","    file = getabsfile(object, _filename)\n","           ^^^^^^^^^^^^^^^^^^^^^^^^^^^^^\n","  File \"/usr/lib/python3.11/inspect.py\", line 964, in getabsfile\n","    return os.path.normcase(os.path.abspath(_filename))\n","                            ^^^^^^^^^^^^^^^^^^^^^^^^^^\n","  File \"\u003cfrozen posixpath\u003e\", line 404, in abspath\n","OSError: [Errno 107] Transport endpoint is not connected\n","Traceback (most recent call last):\n","  File \"/usr/local/lib/python3.11/dist-packages/IPython/core/interactiveshell.py\", line 3553, in run_code\n","    exec(code_obj, self.user_global_ns, self.user_ns)\n","  File \"\u003cipython-input-3-25625e750ebd\u003e\", line 12, in \u003ccell line: 0\u003e\n","    get_ipython().run_line_magic('cd', '\"{path}\"')\n","  File \"/usr/local/lib/python3.11/dist-packages/IPython/core/interactiveshell.py\", line 2418, in run_line_magic\n","    result = fn(*args, **kwargs)\n","             ^^^^^^^^^^^^^^^^^^^\n","  File \"\u003cdecorator-gen-85\u003e\", line 2, in cd\n","  File \"/usr/local/lib/python3.11/dist-packages/IPython/core/magic.py\", line 187, in \u003clambda\u003e\n","    call = lambda f, *a, **k: f(*a, **k)\n","                              ^^^^^^^^^^\n","  File \"/usr/local/lib/python3.11/dist-packages/IPython/core/magics/osm.py\", line 342, in cd\n","    oldcwd = os.getcwd()\n","             ^^^^^^^^^^^\n","OSError: [Errno 107] Transport endpoint is not connected\n","\n","During handling of the above exception, another exception occurred:\n","\n","Traceback (most recent call last):\n","  File \"/usr/local/lib/python3.11/dist-packages/IPython/core/interactiveshell.py\", line 2099, in showtraceback\n","    stb = value._render_traceback_()\n","          ^^^^^^^^^^^^^^^^^^^^^^^^\n","AttributeError: 'OSError' object has no attribute '_render_traceback_'\n","\n","During handling of the above exception, another exception occurred:\n","\n","Traceback (most recent call last):\n","  File \"/usr/local/lib/python3.11/dist-packages/IPython/core/interactiveshell.py\", line 3473, in run_ast_nodes\n","    if (await self.run_code(code, result,  async_=asy)):\n","        ^^^^^^^^^^^^^^^^^^^^^^^^^^^^^^^^^^^^^^^^^^^^^^\n","  File \"/usr/local/lib/python3.11/dist-packages/IPython/core/interactiveshell.py\", line 3575, in run_code\n","    self.showtraceback(running_compiled_code=True)\n","  File \"/usr/local/lib/python3.11/dist-packages/IPython/core/interactiveshell.py\", line 2101, in showtraceback\n","    stb = self.InteractiveTB.structured_traceback(etype,\n","          ^^^^^^^^^^^^^^^^^^^^^^^^^^^^^^^^^^^^^^^^^^^^^^\n","  File \"/usr/local/lib/python3.11/dist-packages/IPython/core/ultratb.py\", line 1367, in structured_traceback\n","    return FormattedTB.structured_traceback(\n","           ^^^^^^^^^^^^^^^^^^^^^^^^^^^^^^^^^\n","  File \"/usr/local/lib/python3.11/dist-packages/IPython/core/ultratb.py\", line 1267, in structured_traceback\n","    return VerboseTB.structured_traceback(\n","           ^^^^^^^^^^^^^^^^^^^^^^^^^^^^^^^\n","  File \"/usr/local/lib/python3.11/dist-packages/IPython/core/ultratb.py\", line 1124, in structured_traceback\n","    formatted_exception = self.format_exception_as_a_whole(etype, evalue, etb, number_of_lines_of_context,\n","                          ^^^^^^^^^^^^^^^^^^^^^^^^^^^^^^^^^^^^^^^^^^^^^^^^^^^^^^^^^^^^^^^^^^^^^^^^^^^^^^^^\n","  File \"/usr/local/lib/python3.11/dist-packages/IPython/core/ultratb.py\", line 1082, in format_exception_as_a_whole\n","    last_unique, recursion_repeat = find_recursion(orig_etype, evalue, records)\n","                                    ^^^^^^^^^^^^^^^^^^^^^^^^^^^^^^^^^^^^^^^^^^^\n","  File \"/usr/local/lib/python3.11/dist-packages/IPython/core/ultratb.py\", line 382, in find_recursion\n","    return len(records), 0\n","           ^^^^^^^^^^^^\n","TypeError: object of type 'NoneType' has no len()\n","\n","During handling of the above exception, another exception occurred:\n","\n","Traceback (most recent call last):\n","  File \"/usr/local/lib/python3.11/dist-packages/IPython/core/interactiveshell.py\", line 2099, in showtraceback\n","    stb = value._render_traceback_()\n","          ^^^^^^^^^^^^^^^^^^^^^^^^\n","AttributeError: 'TypeError' object has no attribute '_render_traceback_'\n","\n","During handling of the above exception, another exception occurred:\n","\n","Traceback (most recent call last):\n","  File \"/usr/local/lib/python3.11/dist-packages/IPython/core/ultratb.py\", line 1101, in get_records\n","    return _fixed_getinnerframes(etb, number_of_lines_of_context, tb_offset)\n","           ^^^^^^^^^^^^^^^^^^^^^^^^^^^^^^^^^^^^^^^^^^^^^^^^^^^^^^^^^^^^^^^^^\n","  File \"/usr/local/lib/python3.11/dist-packages/IPython/core/ultratb.py\", line 248, in wrapped\n","    return f(*args, **kwargs)\n","           ^^^^^^^^^^^^^^^^^^\n","  File \"/usr/local/lib/python3.11/dist-packages/IPython/core/ultratb.py\", line 281, in _fixed_getinnerframes\n","    records = fix_frame_records_filenames(inspect.getinnerframes(etb, context))\n","                                          ^^^^^^^^^^^^^^^^^^^^^^^^^^^^^^^^^^^^\n","  File \"/usr/lib/python3.11/inspect.py\", line 1739, in getinnerframes\n","    traceback_info = getframeinfo(tb, context)\n","                     ^^^^^^^^^^^^^^^^^^^^^^^^^\n","  File \"/usr/lib/python3.11/inspect.py\", line 1684, in getframeinfo\n","    filename = getsourcefile(frame) or getfile(frame)\n","               ^^^^^^^^^^^^^^^^^^^^\n","  File \"/usr/lib/python3.11/inspect.py\", line 948, in getsourcefile\n","    module = getmodule(object, filename)\n","             ^^^^^^^^^^^^^^^^^^^^^^^^^^^\n","  File \"/usr/lib/python3.11/inspect.py\", line 980, in getmodule\n","    file = getabsfile(object, _filename)\n","           ^^^^^^^^^^^^^^^^^^^^^^^^^^^^^\n","  File \"/usr/lib/python3.11/inspect.py\", line 964, in getabsfile\n","    return os.path.normcase(os.path.abspath(_filename))\n","                            ^^^^^^^^^^^^^^^^^^^^^^^^^^\n","  File \"\u003cfrozen posixpath\u003e\", line 404, in abspath\n","OSError: [Errno 107] Transport endpoint is not connected\n","Traceback (most recent call last):\n","  File \"/usr/local/lib/python3.11/dist-packages/IPython/core/interactiveshell.py\", line 3553, in run_code\n","    exec(code_obj, self.user_global_ns, self.user_ns)\n","  File \"\u003cipython-input-3-25625e750ebd\u003e\", line 12, in \u003ccell line: 0\u003e\n","    get_ipython().run_line_magic('cd', '\"{path}\"')\n","  File \"/usr/local/lib/python3.11/dist-packages/IPython/core/interactiveshell.py\", line 2418, in run_line_magic\n","    result = fn(*args, **kwargs)\n","             ^^^^^^^^^^^^^^^^^^^\n","  File \"\u003cdecorator-gen-85\u003e\", line 2, in cd\n","  File \"/usr/local/lib/python3.11/dist-packages/IPython/core/magic.py\", line 187, in \u003clambda\u003e\n","    call = lambda f, *a, **k: f(*a, **k)\n","                              ^^^^^^^^^^\n","  File \"/usr/local/lib/python3.11/dist-packages/IPython/core/magics/osm.py\", line 342, in cd\n","    oldcwd = os.getcwd()\n","             ^^^^^^^^^^^\n","OSError: [Errno 107] Transport endpoint is not connected\n","\n","During handling of the above exception, another exception occurred:\n","\n","Traceback (most recent call last):\n","  File \"/usr/local/lib/python3.11/dist-packages/IPython/core/interactiveshell.py\", line 2099, in showtraceback\n","    stb = value._render_traceback_()\n","          ^^^^^^^^^^^^^^^^^^^^^^^^\n","AttributeError: 'OSError' object has no attribute '_render_traceback_'\n","\n","During handling of the above exception, another exception occurred:\n","\n","Traceback (most recent call last):\n","  File \"/usr/local/lib/python3.11/dist-packages/IPython/core/interactiveshell.py\", line 3473, in run_ast_nodes\n","    if (await self.run_code(code, result,  async_=asy)):\n","        ^^^^^^^^^^^^^^^^^^^^^^^^^^^^^^^^^^^^^^^^^^^^^^\n","  File \"/usr/local/lib/python3.11/dist-packages/IPython/core/interactiveshell.py\", line 3575, in run_code\n","    self.showtraceback(running_compiled_code=True)\n","  File \"/usr/local/lib/python3.11/dist-packages/IPython/core/interactiveshell.py\", line 2101, in showtraceback\n","    stb = self.InteractiveTB.structured_traceback(etype,\n","          ^^^^^^^^^^^^^^^^^^^^^^^^^^^^^^^^^^^^^^^^^^^^^^\n","  File \"/usr/local/lib/python3.11/dist-packages/IPython/core/ultratb.py\", line 1367, in structured_traceback\n","    return FormattedTB.structured_traceback(\n","           ^^^^^^^^^^^^^^^^^^^^^^^^^^^^^^^^^\n","  File \"/usr/local/lib/python3.11/dist-packages/IPython/core/ultratb.py\", line 1267, in structured_traceback\n","    return VerboseTB.structured_traceback(\n","           ^^^^^^^^^^^^^^^^^^^^^^^^^^^^^^^\n","  File \"/usr/local/lib/python3.11/dist-packages/IPython/core/ultratb.py\", line 1124, in structured_traceback\n","    formatted_exception = self.format_exception_as_a_whole(etype, evalue, etb, number_of_lines_of_context,\n","                          ^^^^^^^^^^^^^^^^^^^^^^^^^^^^^^^^^^^^^^^^^^^^^^^^^^^^^^^^^^^^^^^^^^^^^^^^^^^^^^^^\n","  File \"/usr/local/lib/python3.11/dist-packages/IPython/core/ultratb.py\", line 1082, in format_exception_as_a_whole\n","    last_unique, recursion_repeat = find_recursion(orig_etype, evalue, records)\n","                                    ^^^^^^^^^^^^^^^^^^^^^^^^^^^^^^^^^^^^^^^^^^^\n","  File \"/usr/local/lib/python3.11/dist-packages/IPython/core/ultratb.py\", line 382, in find_recursion\n","    return len(records), 0\n","           ^^^^^^^^^^^^\n","TypeError: object of type 'NoneType' has no len()\n","\n","During handling of the above exception, another exception occurred:\n","\n","Traceback (most recent call last):\n","  File \"/usr/local/lib/python3.11/dist-packages/IPython/core/interactiveshell.py\", line 2099, in showtraceback\n","    stb = value._render_traceback_()\n","          ^^^^^^^^^^^^^^^^^^^^^^^^\n","AttributeError: 'TypeError' object has no attribute '_render_traceback_'\n","\n","During handling of the above exception, another exception occurred:\n","\n","Traceback (most recent call last):\n","  File \"/usr/local/lib/python3.11/dist-packages/IPython/core/interactiveshell.py\", line 3030, in _run_cell\n","    return runner(coro)\n","           ^^^^^^^^^^^^\n","  File \"/usr/local/lib/python3.11/dist-packages/IPython/core/async_helpers.py\", line 78, in _pseudo_sync_runner\n","    coro.send(None)\n","  File \"/usr/local/lib/python3.11/dist-packages/IPython/core/interactiveshell.py\", line 3257, in run_cell_async\n","    has_raised = await self.run_ast_nodes(code_ast.body, cell_name,\n","                 ^^^^^^^^^^^^^^^^^^^^^^^^^^^^^^^^^^^^^^^^^^^^^^^^^^\n","  File \"/usr/local/lib/python3.11/dist-packages/IPython/core/interactiveshell.py\", line 3492, in run_ast_nodes\n","    self.showtraceback()\n","  File \"/usr/local/lib/python3.11/dist-packages/IPython/core/interactiveshell.py\", line 2101, in showtraceback\n","    stb = self.InteractiveTB.structured_traceback(etype,\n","          ^^^^^^^^^^^^^^^^^^^^^^^^^^^^^^^^^^^^^^^^^^^^^^\n","  File \"/usr/local/lib/python3.11/dist-packages/IPython/core/ultratb.py\", line 1367, in structured_traceback\n","    return FormattedTB.structured_traceback(\n","           ^^^^^^^^^^^^^^^^^^^^^^^^^^^^^^^^^\n","  File \"/usr/local/lib/python3.11/dist-packages/IPython/core/ultratb.py\", line 1267, in structured_traceback\n","    return VerboseTB.structured_traceback(\n","           ^^^^^^^^^^^^^^^^^^^^^^^^^^^^^^^\n","  File \"/usr/local/lib/python3.11/dist-packages/IPython/core/ultratb.py\", line 1142, in structured_traceback\n","    formatted_exceptions += self.format_exception_as_a_whole(etype, evalue, etb, lines_of_context,\n","                            ^^^^^^^^^^^^^^^^^^^^^^^^^^^^^^^^^^^^^^^^^^^^^^^^^^^^^^^^^^^^^^^^^^^^^^\n","  File \"/usr/local/lib/python3.11/dist-packages/IPython/core/ultratb.py\", line 1082, in format_exception_as_a_whole\n","    last_unique, recursion_repeat = find_recursion(orig_etype, evalue, records)\n","                                    ^^^^^^^^^^^^^^^^^^^^^^^^^^^^^^^^^^^^^^^^^^^\n","  File \"/usr/local/lib/python3.11/dist-packages/IPython/core/ultratb.py\", line 382, in find_recursion\n","    return len(records), 0\n","           ^^^^^^^^^^^^\n","TypeError: object of type 'NoneType' has no len()\n","\n","During handling of the above exception, another exception occurred:\n","\n","Traceback (most recent call last):\n","  File \"/usr/local/lib/python3.11/dist-packages/IPython/core/interactiveshell.py\", line 2099, in showtraceback\n","    stb = value._render_traceback_()\n","          ^^^^^^^^^^^^^^^^^^^^^^^^\n","AttributeError: 'TypeError' object has no attribute '_render_traceback_'\n","\n","During handling of the above exception, another exception occurred:\n","\n","Traceback (most recent call last):\n","  File \"/usr/local/lib/python3.11/dist-packages/IPython/core/ultratb.py\", line 1101, in get_records\n","    return _fixed_getinnerframes(etb, number_of_lines_of_context, tb_offset)\n","           ^^^^^^^^^^^^^^^^^^^^^^^^^^^^^^^^^^^^^^^^^^^^^^^^^^^^^^^^^^^^^^^^^\n","  File \"/usr/local/lib/python3.11/dist-packages/IPython/core/ultratb.py\", line 248, in wrapped\n","    return f(*args, **kwargs)\n","           ^^^^^^^^^^^^^^^^^^\n","  File \"/usr/local/lib/python3.11/dist-packages/IPython/core/ultratb.py\", line 281, in _fixed_getinnerframes\n","    records = fix_frame_records_filenames(inspect.getinnerframes(etb, context))\n","                                          ^^^^^^^^^^^^^^^^^^^^^^^^^^^^^^^^^^^^\n","  File \"/usr/lib/python3.11/inspect.py\", line 1739, in getinnerframes\n","    traceback_info = getframeinfo(tb, context)\n","                     ^^^^^^^^^^^^^^^^^^^^^^^^^\n","  File \"/usr/lib/python3.11/inspect.py\", line 1684, in getframeinfo\n","    filename = getsourcefile(frame) or getfile(frame)\n","               ^^^^^^^^^^^^^^^^^^^^\n","  File \"/usr/lib/python3.11/inspect.py\", line 948, in getsourcefile\n","    module = getmodule(object, filename)\n","             ^^^^^^^^^^^^^^^^^^^^^^^^^^^\n","  File \"/usr/lib/python3.11/inspect.py\", line 980, in getmodule\n","    file = getabsfile(object, _filename)\n","           ^^^^^^^^^^^^^^^^^^^^^^^^^^^^^\n","  File \"/usr/lib/python3.11/inspect.py\", line 964, in getabsfile\n","    return os.path.normcase(os.path.abspath(_filename))\n","                            ^^^^^^^^^^^^^^^^^^^^^^^^^^\n","  File \"\u003cfrozen posixpath\u003e\", line 404, in abspath\n","OSError: [Errno 107] Transport endpoint is not connected\n"]}],"source":["# Mounting/updating Drive\n","if DRIVEmount:\n","  if os.path.ismount('/content/drive'):\n","    drive.flush_and_unmount()\n","  drive.mount('/content/drive')\n","\n","  # Selecting correct path (eventually insert the correct one for ur shared drive)\n","  paths = [\"/content/drive/Othercomputers/Il mio laptop/Matteo/Magistrale/Un. of Edinburgh/Attività/HackTheBurgh\",\n","          \"/content/drive/MyDrive/HackTheBurgh\"]\n","  for path in paths:\n","    if Path(path).exists():\n","      %cd \"{path}\"\n","  %ls"]},{"cell_type":"code","execution_count":2,"metadata":{"colab":{"base_uri":"https://localhost:8080/","height":211},"executionInfo":{"elapsed":72,"status":"error","timestamp":1740845042286,"user":{"displayName":"Matteo Spadaccia","userId":"07886475442363014775"},"user_tz":0},"id":"OvHtC9XkZLr7","outputId":"eada4120-0e11-4680-91ed-9d99cc490c53"},"outputs":[{"ename":"NameError","evalue":"name 'GHpush' is not defined","output_type":"error","traceback":["\u001b[0;31m---------------------------------------------------------------------------\u001b[0m","\u001b[0;31mNameError\u001b[0m                                 Traceback (most recent call last)","\u001b[0;32m\u003cipython-input-2-0ac28e80d088\u003e\u001b[0m in \u001b[0;36m\u003ccell line: 0\u003e\u001b[0;34m()\u001b[0m\n\u001b[1;32m      1\u001b[0m \u001b[0;31m# GitHub interaction initialization\u001b[0m\u001b[0;34m\u001b[0m\u001b[0;34m\u001b[0m\u001b[0m\n\u001b[0;32m----\u003e 2\u001b[0;31m \u001b[0;32mif\u001b[0m \u001b[0mGHpush\u001b[0m\u001b[0;34m:\u001b[0m\u001b[0;34m\u001b[0m\u001b[0;34m\u001b[0m\u001b[0m\n\u001b[0m\u001b[1;32m      3\u001b[0m   \u001b[0mget_ipython\u001b[0m\u001b[0;34m(\u001b[0m\u001b[0;34m)\u001b[0m\u001b[0;34m.\u001b[0m\u001b[0msystem\u001b[0m\u001b[0;34m(\u001b[0m\u001b[0;34m' git clone -l -s https://github.com/MatSpad/Advanced-Coding-for-Data-Analytics-Project-2024.git cloned-repository'\u001b[0m\u001b[0;34m)\u001b[0m\u001b[0;34m\u001b[0m\u001b[0;34m\u001b[0m\u001b[0m\n\u001b[1;32m      4\u001b[0m   \u001b[0mget_ipython\u001b[0m\u001b[0;34m(\u001b[0m\u001b[0;34m)\u001b[0m\u001b[0;34m.\u001b[0m\u001b[0msystem\u001b[0m\u001b[0;34m(\u001b[0m\u001b[0;34m'git init'\u001b[0m\u001b[0;34m)\u001b[0m\u001b[0;34m\u001b[0m\u001b[0;34m\u001b[0m\u001b[0m\n\u001b[1;32m      5\u001b[0m   \u001b[0mget_ipython\u001b[0m\u001b[0;34m(\u001b[0m\u001b[0;34m)\u001b[0m\u001b[0;34m.\u001b[0m\u001b[0msystem\u001b[0m\u001b[0;34m(\u001b[0m\u001b[0;34m'git remote add origin https://github.com/YOUR_GITHUB_USERNAME/YOUR_REPO_NAME.git'\u001b[0m\u001b[0;34m)\u001b[0m\u001b[0;34m\u001b[0m\u001b[0;34m\u001b[0m\u001b[0m\n","\u001b[0;31mNameError\u001b[0m: name 'GHpush' is not defined"]}],"source":["# GitHub interaction initialization\n","if GHpush:\n","  !git config --global user.name \"AthinaKyriakou\"\n","  !git config --global user.email \"34518449+AthinaKyriakou@users.noreply.github.com\"\n","  !git init\n","  !git remote add origin https://github.com/YOUR_GITHUB_USERNAME/YOUR_REPO_NAME.git\n","  !git add .\n","  timestamp = datetime.now().strftime(\"%Y-%m-%d %H:%M:%S\")\n","  !git commit -m \"Commit at {timestamp}\"\n","  !git push -u origin master"]}],"metadata":{"colab":{"authorship_tag":"ABX9TyPW7FuicSlccVGfDC+y3EQN","name":"","version":""},"kernelspec":{"display_name":"Python 3","name":"python3"},"language_info":{"name":"python"}},"nbformat":4,"nbformat_minor":0}